[2024-01-05T14:20:36.506+0000] {taskinstance.py:1957} INFO - Dependencies all met for dep_context=non-requeueable deps ti=<TaskInstance: create_or_update.create_or_update scheduled__2024-01-01T00:00:00+00:00 [queued]>
[2024-01-05T14:20:36.510+0000] {taskinstance.py:1957} INFO - Dependencies all met for dep_context=requeueable deps ti=<TaskInstance: create_or_update.create_or_update scheduled__2024-01-01T00:00:00+00:00 [queued]>
[2024-01-05T14:20:36.510+0000] {taskinstance.py:2171} INFO - Starting attempt 3 of 3
[2024-01-05T14:20:36.516+0000] {taskinstance.py:2192} INFO - Executing <Task(PythonOperator): create_or_update> on 2024-01-01 00:00:00+00:00
[2024-01-05T14:20:36.519+0000] {standard_task_runner.py:60} INFO - Started process 205 to run task
[2024-01-05T14:20:36.521+0000] {standard_task_runner.py:87} INFO - Running: ['***', 'tasks', 'run', 'create_or_update', 'create_or_update', 'scheduled__2024-01-01T00:00:00+00:00', '--job-id', '13', '--raw', '--subdir', 'DAGS_FOLDER/create_or_update.py', '--cfg-path', '/tmp/tmp75a97zpi']
[2024-01-05T14:20:36.522+0000] {standard_task_runner.py:88} INFO - Job 13: Subtask create_or_update
[2024-01-05T14:20:36.546+0000] {task_command.py:423} INFO - Running <TaskInstance: create_or_update.create_or_update scheduled__2024-01-01T00:00:00+00:00 [running]> on host c25267c2e107
[2024-01-05T14:20:36.579+0000] {taskinstance.py:2481} INFO - Exporting env vars: AIRFLOW_CTX_DAG_OWNER='***' AIRFLOW_CTX_DAG_ID='create_or_update' AIRFLOW_CTX_TASK_ID='create_or_update' AIRFLOW_CTX_EXECUTION_DATE='2024-01-01T00:00:00+00:00' AIRFLOW_CTX_TRY_NUMBER='3' AIRFLOW_CTX_DAG_RUN_ID='scheduled__2024-01-01T00:00:00+00:00'
[2024-01-05T14:20:36.717+0000] {taskinstance.py:2699} ERROR - Task failed with exception
Traceback (most recent call last):
  File "/home/airflow/.local/lib/python3.8/site-packages/airflow/models/taskinstance.py", line 433, in _execute_task
    result = execute_callable(context=context, **execute_callable_kwargs)
  File "/home/airflow/.local/lib/python3.8/site-packages/airflow/operators/python.py", line 199, in execute
    return_value = self.execute_callable()
  File "/home/airflow/.local/lib/python3.8/site-packages/airflow/operators/python.py", line 216, in execute_callable
    return self.python_callable(*self.op_args, **self.op_kwargs)
  File "/opt/airflow/dags/create_or_update.py", line 45, in create_or_update
    cluster = Cluster(['cassandra_db.airflow-metadata-kafka-cassandra_confluent'], auth_provider=auth_provider)
  File "cassandra/cluster.py", line 1191, in cassandra.cluster.Cluster.__init__
cassandra.UnresolvableContactPoints: {}
[2024-01-05T14:20:36.724+0000] {taskinstance.py:1138} INFO - Marking task as FAILED. dag_id=create_or_update, task_id=create_or_update, execution_date=20240101T000000, start_date=20240105T142036, end_date=20240105T142036
[2024-01-05T14:20:36.730+0000] {standard_task_runner.py:107} ERROR - Failed to execute job 13 for task create_or_update ({}; 205)
[2024-01-05T14:20:36.775+0000] {local_task_job_runner.py:234} INFO - Task exited with return code 1
[2024-01-05T14:20:36.785+0000] {taskinstance.py:3281} INFO - 0 downstream tasks scheduled from follow-on schedule check
[2024-01-05T17:35:30.580+0000] {taskinstance.py:1957} INFO - Dependencies all met for dep_context=non-requeueable deps ti=<TaskInstance: create_or_update.create_or_update scheduled__2024-01-01T00:00:00+00:00 [queued]>
[2024-01-05T17:35:30.585+0000] {taskinstance.py:1957} INFO - Dependencies all met for dep_context=requeueable deps ti=<TaskInstance: create_or_update.create_or_update scheduled__2024-01-01T00:00:00+00:00 [queued]>
[2024-01-05T17:35:30.586+0000] {taskinstance.py:2171} INFO - Starting attempt 3 of 3
[2024-01-05T17:35:30.593+0000] {taskinstance.py:2192} INFO - Executing <Task(PythonOperator): create_or_update> on 2024-01-01 00:00:00+00:00
[2024-01-05T17:35:30.596+0000] {standard_task_runner.py:60} INFO - Started process 99 to run task
[2024-01-05T17:35:30.598+0000] {standard_task_runner.py:87} INFO - Running: ['***', 'tasks', 'run', 'create_or_update', 'create_or_update', 'scheduled__2024-01-01T00:00:00+00:00', '--job-id', '26', '--raw', '--subdir', 'DAGS_FOLDER/create_or_update.py', '--cfg-path', '/tmp/tmp254l_5j3']
[2024-01-05T17:35:30.599+0000] {standard_task_runner.py:88} INFO - Job 26: Subtask create_or_update
[2024-01-05T17:35:30.624+0000] {task_command.py:423} INFO - Running <TaskInstance: create_or_update.create_or_update scheduled__2024-01-01T00:00:00+00:00 [running]> on host d9447f6fb5a6
[2024-01-05T17:35:30.659+0000] {taskinstance.py:2481} INFO - Exporting env vars: AIRFLOW_CTX_DAG_OWNER='data-eng' AIRFLOW_CTX_DAG_ID='create_or_update' AIRFLOW_CTX_TASK_ID='create_or_update' AIRFLOW_CTX_EXECUTION_DATE='2024-01-01T00:00:00+00:00' AIRFLOW_CTX_TRY_NUMBER='3' AIRFLOW_CTX_DAG_RUN_ID='scheduled__2024-01-01T00:00:00+00:00'
[2024-01-05T17:35:30.662+0000] {create_or_update.py:46} WARNING - Cluster.__init__ called with contact_points specified, but no load_balancing_policy. In the next major version, this will raise an error; please specify a load-balancing policy. (contact_points = ['host.docker.internal'], lbp = None)
[2024-01-05T17:35:30.669+0000] {create_or_update.py:47} WARNING - Downgrading core protocol version from 66 to 65 for 192.168.65.254:9042. To avoid this, it is best practice to explicitly set Cluster(protocol_version) to the version supported by your cluster. http://datastax.github.io/python-driver/api/cassandra/cluster.html#cassandra.cluster.Cluster.protocol_version
[2024-01-05T17:35:30.672+0000] {create_or_update.py:47} WARNING - Downgrading core protocol version from 65 to 5 for 192.168.65.254:9042. To avoid this, it is best practice to explicitly set Cluster(protocol_version) to the version supported by your cluster. http://datastax.github.io/python-driver/api/cassandra/cluster.html#cassandra.cluster.Cluster.protocol_version
[2024-01-05T17:35:30.692+0000] {asyncorereactor.py:448} WARNING - An authentication challenge was not sent, this is suspicious because the driver expects authentication (configured authenticator = PlainTextAuthenticator)
[2024-01-05T17:35:30.705+0000] {policies.py:289} INFO - Using datacenter 'datacenter1' for DCAwareRoundRobinPolicy (via host '192.168.65.254:9042'); if incorrect, please specify a local_dc to the constructor, or limit contact points to local cluster nodes
[2024-01-05T17:35:30.862+0000] {asyncorereactor.py:448} WARNING - An authentication challenge was not sent, this is suspicious because the driver expects authentication (configured authenticator = PlainTextAuthenticator)
[2024-01-05T17:35:30.917+0000] {logging_mixin.py:188} INFO - Keyspace created successfully
[2024-01-05T17:35:31.043+0000] {logging_mixin.py:188} INFO - Table created successfully
[2024-01-05T17:35:31.044+0000] {python.py:201} INFO - Done. Returned value was: None
[2024-01-05T17:35:31.049+0000] {taskinstance.py:1138} INFO - Marking task as SUCCESS. dag_id=create_or_update, task_id=create_or_update, execution_date=20240101T000000, start_date=20240105T173530, end_date=20240105T173531
[2024-01-05T17:35:31.092+0000] {local_task_job_runner.py:234} INFO - Task exited with return code 0
[2024-01-05T17:35:31.103+0000] {taskinstance.py:3281} INFO - 0 downstream tasks scheduled from follow-on schedule check
