[2024-01-05T14:25:21.400+0000] {taskinstance.py:1957} INFO - Dependencies all met for dep_context=non-requeueable deps ti=<TaskInstance: create_or_update.create_or_update scheduled__2024-01-01T00:00:00+00:00 [queued]>
[2024-01-05T14:25:21.404+0000] {taskinstance.py:1957} INFO - Dependencies all met for dep_context=requeueable deps ti=<TaskInstance: create_or_update.create_or_update scheduled__2024-01-01T00:00:00+00:00 [queued]>
[2024-01-05T14:25:21.404+0000] {taskinstance.py:2171} INFO - Starting attempt 4 of 4
[2024-01-05T14:25:21.410+0000] {taskinstance.py:2192} INFO - Executing <Task(PythonOperator): create_or_update> on 2024-01-01 00:00:00+00:00
[2024-01-05T14:25:21.413+0000] {standard_task_runner.py:60} INFO - Started process 279 to run task
[2024-01-05T14:25:21.415+0000] {standard_task_runner.py:87} INFO - Running: ['***', 'tasks', 'run', 'create_or_update', 'create_or_update', 'scheduled__2024-01-01T00:00:00+00:00', '--job-id', '14', '--raw', '--subdir', 'DAGS_FOLDER/create_or_update.py', '--cfg-path', '/tmp/tmp4xzuz3pc']
[2024-01-05T14:25:21.416+0000] {standard_task_runner.py:88} INFO - Job 14: Subtask create_or_update
[2024-01-05T14:25:21.440+0000] {task_command.py:423} INFO - Running <TaskInstance: create_or_update.create_or_update scheduled__2024-01-01T00:00:00+00:00 [running]> on host c25267c2e107
[2024-01-05T14:25:21.470+0000] {taskinstance.py:2481} INFO - Exporting env vars: AIRFLOW_CTX_DAG_OWNER='***' AIRFLOW_CTX_DAG_ID='create_or_update' AIRFLOW_CTX_TASK_ID='create_or_update' AIRFLOW_CTX_EXECUTION_DATE='2024-01-01T00:00:00+00:00' AIRFLOW_CTX_TRY_NUMBER='4' AIRFLOW_CTX_DAG_RUN_ID='scheduled__2024-01-01T00:00:00+00:00'
[2024-01-05T14:25:21.473+0000] {create_or_update.py:46} WARNING - Cluster.__init__ called with contact_points specified, but no load_balancing_policy. In the next major version, this will raise an error; please specify a load-balancing policy. (contact_points = ['172.19.0.3'], lbp = None)
[2024-01-05T14:25:26.481+0000] {create_or_update.py:47} WARNING - [control connection] Error connecting to 172.19.0.3:9042:
Traceback (most recent call last):
  File "cassandra/cluster.py", line 3541, in cassandra.cluster.ControlConnection._reconnect_internal
  File "cassandra/cluster.py", line 3563, in cassandra.cluster.ControlConnection._try_connect
  File "cassandra/cluster.py", line 1630, in cassandra.cluster.Cluster.connection_factory
  File "cassandra/connection.py", line 850, in cassandra.connection.Connection.factory
  File "/home/airflow/.local/lib/python3.8/site-packages/cassandra/io/asyncorereactor.py", line 347, in __init__
    self._connect_socket()
  File "cassandra/connection.py", line 917, in cassandra.connection.Connection._connect_socket
OSError: [Errno None] Tried connecting to [('172.19.0.3', 9042)]. Last error: timed out
[2024-01-05T14:25:26.493+0000] {create_or_update.py:47} ERROR - Control connection failed to connect, shutting down Cluster:
Traceback (most recent call last):
  File "cassandra/cluster.py", line 1700, in cassandra.cluster.Cluster.connect
  File "cassandra/cluster.py", line 3507, in cassandra.cluster.ControlConnection.connect
  File "cassandra/cluster.py", line 3552, in cassandra.cluster.ControlConnection._reconnect_internal
cassandra.cluster.NoHostAvailable: ('Unable to connect to any servers', {'172.19.0.3:9042': OSError(None, "Tried connecting to [('172.19.0.3', 9042)]. Last error: timed out")})
[2024-01-05T14:25:26.495+0000] {taskinstance.py:2699} ERROR - Task failed with exception
Traceback (most recent call last):
  File "/home/airflow/.local/lib/python3.8/site-packages/airflow/models/taskinstance.py", line 433, in _execute_task
    result = execute_callable(context=context, **execute_callable_kwargs)
  File "/home/airflow/.local/lib/python3.8/site-packages/airflow/operators/python.py", line 199, in execute
    return_value = self.execute_callable()
  File "/home/airflow/.local/lib/python3.8/site-packages/airflow/operators/python.py", line 216, in execute_callable
    return self.python_callable(*self.op_args, **self.op_kwargs)
  File "/opt/airflow/dags/create_or_update.py", line 47, in create_or_update
    session = cluster.connect()
  File "cassandra/cluster.py", line 1677, in cassandra.cluster.Cluster.connect
  File "cassandra/cluster.py", line 1713, in cassandra.cluster.Cluster.connect
  File "cassandra/cluster.py", line 1700, in cassandra.cluster.Cluster.connect
  File "cassandra/cluster.py", line 3507, in cassandra.cluster.ControlConnection.connect
  File "cassandra/cluster.py", line 3552, in cassandra.cluster.ControlConnection._reconnect_internal
cassandra.cluster.NoHostAvailable: ('Unable to connect to any servers', {'172.19.0.3:9042': OSError(None, "Tried connecting to [('172.19.0.3', 9042)]. Last error: timed out")})
[2024-01-05T14:25:26.505+0000] {taskinstance.py:1138} INFO - Marking task as FAILED. dag_id=create_or_update, task_id=create_or_update, execution_date=20240101T000000, start_date=20240105T142521, end_date=20240105T142526
[2024-01-05T14:25:26.516+0000] {standard_task_runner.py:107} ERROR - Failed to execute job 14 for task create_or_update (('Unable to connect to any servers', {'172.19.0.3:9042': OSError(None, "Tried connecting to [('172.19.0.3', 9042)]. Last error: timed out")}); 279)
[2024-01-05T14:25:26.529+0000] {local_task_job_runner.py:234} INFO - Task exited with return code 1
[2024-01-05T14:25:26.539+0000] {taskinstance.py:3281} INFO - 0 downstream tasks scheduled from follow-on schedule check
[2024-01-05T17:51:22.281+0000] {taskinstance.py:1957} INFO - Dependencies all met for dep_context=non-requeueable deps ti=<TaskInstance: create_or_update.create_or_update scheduled__2024-01-01T00:00:00+00:00 [queued]>
[2024-01-05T17:51:22.285+0000] {taskinstance.py:1957} INFO - Dependencies all met for dep_context=requeueable deps ti=<TaskInstance: create_or_update.create_or_update scheduled__2024-01-01T00:00:00+00:00 [queued]>
[2024-01-05T17:51:22.285+0000] {taskinstance.py:2171} INFO - Starting attempt 4 of 4
[2024-01-05T17:51:22.292+0000] {taskinstance.py:2192} INFO - Executing <Task(PythonOperator): create_or_update> on 2024-01-01 00:00:00+00:00
[2024-01-05T17:51:22.295+0000] {standard_task_runner.py:60} INFO - Started process 254 to run task
[2024-01-05T17:51:22.298+0000] {standard_task_runner.py:87} INFO - Running: ['***', 'tasks', 'run', 'create_or_update', 'create_or_update', 'scheduled__2024-01-01T00:00:00+00:00', '--job-id', '36', '--raw', '--subdir', 'DAGS_FOLDER/create_or_update.py', '--cfg-path', '/tmp/tmpp6u4ozdg']
[2024-01-05T17:51:22.299+0000] {standard_task_runner.py:88} INFO - Job 36: Subtask create_or_update
[2024-01-05T17:51:22.327+0000] {task_command.py:423} INFO - Running <TaskInstance: create_or_update.create_or_update scheduled__2024-01-01T00:00:00+00:00 [running]> on host d23442f9ddc6
[2024-01-05T17:51:22.365+0000] {taskinstance.py:2481} INFO - Exporting env vars: AIRFLOW_CTX_DAG_OWNER='data-eng' AIRFLOW_CTX_DAG_ID='create_or_update' AIRFLOW_CTX_TASK_ID='create_or_update' AIRFLOW_CTX_EXECUTION_DATE='2024-01-01T00:00:00+00:00' AIRFLOW_CTX_TRY_NUMBER='4' AIRFLOW_CTX_DAG_RUN_ID='scheduled__2024-01-01T00:00:00+00:00'
[2024-01-05T17:51:22.383+0000] {create_or_update.py:46} WARNING - Cluster.__init__ called with contact_points specified, but no load_balancing_policy. In the next major version, this will raise an error; please specify a load-balancing policy. (contact_points = ['host.docker.internal'], lbp = None)
[2024-01-05T17:51:22.391+0000] {create_or_update.py:47} WARNING - Downgrading core protocol version from 66 to 65 for 192.168.65.254:9042. To avoid this, it is best practice to explicitly set Cluster(protocol_version) to the version supported by your cluster. http://datastax.github.io/python-driver/api/cassandra/cluster.html#cassandra.cluster.Cluster.protocol_version
[2024-01-05T17:51:22.393+0000] {create_or_update.py:47} WARNING - Downgrading core protocol version from 65 to 5 for 192.168.65.254:9042. To avoid this, it is best practice to explicitly set Cluster(protocol_version) to the version supported by your cluster. http://datastax.github.io/python-driver/api/cassandra/cluster.html#cassandra.cluster.Cluster.protocol_version
[2024-01-05T17:51:22.397+0000] {asyncorereactor.py:448} WARNING - An authentication challenge was not sent, this is suspicious because the driver expects authentication (configured authenticator = PlainTextAuthenticator)
[2024-01-05T17:51:22.421+0000] {policies.py:289} INFO - Using datacenter 'datacenter1' for DCAwareRoundRobinPolicy (via host '192.168.65.254:9042'); if incorrect, please specify a local_dc to the constructor, or limit contact points to local cluster nodes
[2024-01-05T17:51:22.571+0000] {asyncorereactor.py:448} WARNING - An authentication challenge was not sent, this is suspicious because the driver expects authentication (configured authenticator = PlainTextAuthenticator)
[2024-01-05T17:51:22.614+0000] {logging_mixin.py:188} INFO - Keyspace created successfully
[2024-01-05T17:51:22.722+0000] {logging_mixin.py:188} INFO - Table created successfully
[2024-01-05T17:51:22.723+0000] {python.py:201} INFO - Done. Returned value was: None
[2024-01-05T17:51:22.733+0000] {taskinstance.py:1138} INFO - Marking task as SUCCESS. dag_id=create_or_update, task_id=create_or_update, execution_date=20240101T000000, start_date=20240105T175122, end_date=20240105T175122
[2024-01-05T17:51:22.755+0000] {local_task_job_runner.py:234} INFO - Task exited with return code 0
[2024-01-05T17:51:22.766+0000] {taskinstance.py:3281} INFO - 0 downstream tasks scheduled from follow-on schedule check
