[2024-01-05T14:15:02.598+0000] {taskinstance.py:1957} INFO - Dependencies all met for dep_context=non-requeueable deps ti=<TaskInstance: create_or_update.create_or_update scheduled__2024-01-01T00:00:00+00:00 [queued]>
[2024-01-05T14:15:02.602+0000] {taskinstance.py:1957} INFO - Dependencies all met for dep_context=requeueable deps ti=<TaskInstance: create_or_update.create_or_update scheduled__2024-01-01T00:00:00+00:00 [queued]>
[2024-01-05T14:15:02.602+0000] {taskinstance.py:2171} INFO - Starting attempt 1 of 1
[2024-01-05T14:15:02.608+0000] {taskinstance.py:2192} INFO - Executing <Task(PythonOperator): create_or_update> on 2024-01-01 00:00:00+00:00
[2024-01-05T14:15:02.611+0000] {standard_task_runner.py:60} INFO - Started process 114 to run task
[2024-01-05T14:15:02.613+0000] {standard_task_runner.py:87} INFO - Running: ['***', 'tasks', 'run', 'create_or_update', 'create_or_update', 'scheduled__2024-01-01T00:00:00+00:00', '--job-id', '11', '--raw', '--subdir', 'DAGS_FOLDER/create_or_update.py', '--cfg-path', '/tmp/tmpmmprt52q']
[2024-01-05T14:15:02.614+0000] {standard_task_runner.py:88} INFO - Job 11: Subtask create_or_update
[2024-01-05T14:15:02.638+0000] {task_command.py:423} INFO - Running <TaskInstance: create_or_update.create_or_update scheduled__2024-01-01T00:00:00+00:00 [running]> on host c25267c2e107
[2024-01-05T14:15:02.669+0000] {taskinstance.py:2481} INFO - Exporting env vars: AIRFLOW_CTX_DAG_OWNER='***' AIRFLOW_CTX_DAG_ID='create_or_update' AIRFLOW_CTX_TASK_ID='create_or_update' AIRFLOW_CTX_EXECUTION_DATE='2024-01-01T00:00:00+00:00' AIRFLOW_CTX_TRY_NUMBER='1' AIRFLOW_CTX_DAG_RUN_ID='scheduled__2024-01-01T00:00:00+00:00'
[2024-01-05T14:15:02.781+0000] {taskinstance.py:2699} ERROR - Task failed with exception
Traceback (most recent call last):
  File "/home/airflow/.local/lib/python3.8/site-packages/airflow/models/taskinstance.py", line 433, in _execute_task
    result = execute_callable(context=context, **execute_callable_kwargs)
  File "/home/airflow/.local/lib/python3.8/site-packages/airflow/operators/python.py", line 199, in execute
    return_value = self.execute_callable()
  File "/home/airflow/.local/lib/python3.8/site-packages/airflow/operators/python.py", line 216, in execute_callable
    return self.python_callable(*self.op_args, **self.op_kwargs)
  File "/opt/airflow/dags/create_or_update.py", line 43, in create_or_update
    cluster = Cluster(['cassandra'], auth_provider=auth_provider)
  File "cassandra/cluster.py", line 1191, in cassandra.cluster.Cluster.__init__
cassandra.UnresolvableContactPoints: {}
[2024-01-05T14:15:02.789+0000] {taskinstance.py:1138} INFO - Marking task as FAILED. dag_id=create_or_update, task_id=create_or_update, execution_date=20240101T000000, start_date=20240105T141502, end_date=20240105T141502
[2024-01-05T14:15:02.797+0000] {standard_task_runner.py:107} ERROR - Failed to execute job 11 for task create_or_update ({}; 114)
[2024-01-05T14:15:02.832+0000] {local_task_job_runner.py:234} INFO - Task exited with return code 1
[2024-01-05T14:15:02.841+0000] {taskinstance.py:3281} INFO - 0 downstream tasks scheduled from follow-on schedule check
[2024-01-05T17:08:32.740+0000] {taskinstance.py:1957} INFO - Dependencies all met for dep_context=non-requeueable deps ti=<TaskInstance: create_or_update.create_or_update scheduled__2024-01-01T00:00:00+00:00 [queued]>
[2024-01-05T17:08:32.745+0000] {taskinstance.py:1957} INFO - Dependencies all met for dep_context=requeueable deps ti=<TaskInstance: create_or_update.create_or_update scheduled__2024-01-01T00:00:00+00:00 [queued]>
[2024-01-05T17:08:32.745+0000] {taskinstance.py:2171} INFO - Starting attempt 1 of 1
[2024-01-05T17:08:32.753+0000] {taskinstance.py:2192} INFO - Executing <Task(PythonOperator): create_or_update> on 2024-01-01 00:00:00+00:00
[2024-01-05T17:08:32.755+0000] {standard_task_runner.py:60} INFO - Started process 107 to run task
[2024-01-05T17:08:32.758+0000] {standard_task_runner.py:87} INFO - Running: ['***', 'tasks', 'run', 'create_or_update', 'create_or_update', 'scheduled__2024-01-01T00:00:00+00:00', '--job-id', '12', '--raw', '--subdir', 'DAGS_FOLDER/create_or_update.py', '--cfg-path', '/tmp/tmpxesjwquk']
[2024-01-05T17:08:32.759+0000] {standard_task_runner.py:88} INFO - Job 12: Subtask create_or_update
[2024-01-05T17:08:32.785+0000] {task_command.py:423} INFO - Running <TaskInstance: create_or_update.create_or_update scheduled__2024-01-01T00:00:00+00:00 [running]> on host b40758ebccc6
[2024-01-05T17:08:32.822+0000] {taskinstance.py:2481} INFO - Exporting env vars: AIRFLOW_CTX_DAG_OWNER='***' AIRFLOW_CTX_DAG_ID='create_or_update' AIRFLOW_CTX_TASK_ID='create_or_update' AIRFLOW_CTX_EXECUTION_DATE='2024-01-01T00:00:00+00:00' AIRFLOW_CTX_TRY_NUMBER='1' AIRFLOW_CTX_DAG_RUN_ID='scheduled__2024-01-01T00:00:00+00:00'
[2024-01-05T17:08:32.827+0000] {create_or_update.py:46} WARNING - Cluster.__init__ called with contact_points specified, but no load_balancing_policy. In the next major version, this will raise an error; please specify a load-balancing policy. (contact_points = ['host.docker.internal'], lbp = None)
[2024-01-05T17:08:32.835+0000] {create_or_update.py:47} WARNING - Downgrading core protocol version from 66 to 65 for 192.168.65.254:9042. To avoid this, it is best practice to explicitly set Cluster(protocol_version) to the version supported by your cluster. http://datastax.github.io/python-driver/api/cassandra/cluster.html#cassandra.cluster.Cluster.protocol_version
[2024-01-05T17:08:32.838+0000] {create_or_update.py:47} WARNING - Downgrading core protocol version from 65 to 5 for 192.168.65.254:9042. To avoid this, it is best practice to explicitly set Cluster(protocol_version) to the version supported by your cluster. http://datastax.github.io/python-driver/api/cassandra/cluster.html#cassandra.cluster.Cluster.protocol_version
[2024-01-05T17:08:32.860+0000] {asyncorereactor.py:448} WARNING - An authentication challenge was not sent, this is suspicious because the driver expects authentication (configured authenticator = PlainTextAuthenticator)
[2024-01-05T17:08:32.876+0000] {policies.py:289} INFO - Using datacenter 'datacenter1' for DCAwareRoundRobinPolicy (via host '192.168.65.254:9042'); if incorrect, please specify a local_dc to the constructor, or limit contact points to local cluster nodes
[2024-01-05T17:08:33.031+0000] {asyncorereactor.py:448} WARNING - An authentication challenge was not sent, this is suspicious because the driver expects authentication (configured authenticator = PlainTextAuthenticator)
[2024-01-05T17:08:33.116+0000] {logging_mixin.py:188} INFO - Keyspace created successfully
[2024-01-05T17:08:33.235+0000] {logging_mixin.py:188} INFO - Table created successfully
[2024-01-05T17:08:33.235+0000] {python.py:201} INFO - Done. Returned value was: None
[2024-01-05T17:08:33.241+0000] {taskinstance.py:1138} INFO - Marking task as SUCCESS. dag_id=create_or_update, task_id=create_or_update, execution_date=20240101T000000, start_date=20240105T170832, end_date=20240105T170833
[2024-01-05T17:08:33.260+0000] {local_task_job_runner.py:234} INFO - Task exited with return code 0
[2024-01-05T17:08:33.271+0000] {taskinstance.py:3281} INFO - 0 downstream tasks scheduled from follow-on schedule check
