[2024-01-05T17:45:26.329+0000] {taskinstance.py:1957} INFO - Dependencies all met for dep_context=non-requeueable deps ti=<TaskInstance: create_topic.create_topic scheduled__2024-01-01T00:00:00+00:00 [queued]>
[2024-01-05T17:45:26.334+0000] {taskinstance.py:1957} INFO - Dependencies all met for dep_context=requeueable deps ti=<TaskInstance: create_topic.create_topic scheduled__2024-01-01T00:00:00+00:00 [queued]>
[2024-01-05T17:45:26.334+0000] {taskinstance.py:2171} INFO - Starting attempt 3 of 3
[2024-01-05T17:45:26.340+0000] {taskinstance.py:2192} INFO - Executing <Task(PythonOperator): create_topic> on 2024-01-01 00:00:00+00:00
[2024-01-05T17:45:26.343+0000] {standard_task_runner.py:60} INFO - Started process 143 to run task
[2024-01-05T17:45:26.345+0000] {standard_task_runner.py:87} INFO - Running: ['***', 'tasks', 'run', 'create_topic', 'create_topic', 'scheduled__2024-01-01T00:00:00+00:00', '--job-id', '32', '--raw', '--subdir', 'DAGS_FOLDER/create_topic.py', '--cfg-path', '/tmp/tmplelx4g_8']
[2024-01-05T17:45:26.346+0000] {standard_task_runner.py:88} INFO - Job 32: Subtask create_topic
[2024-01-05T17:45:26.373+0000] {task_command.py:423} INFO - Running <TaskInstance: create_topic.create_topic scheduled__2024-01-01T00:00:00+00:00 [running]> on host d23442f9ddc6
[2024-01-05T17:45:26.411+0000] {taskinstance.py:2481} INFO - Exporting env vars: AIRFLOW_CTX_DAG_OWNER='data-eng' AIRFLOW_CTX_DAG_ID='create_topic' AIRFLOW_CTX_TASK_ID='create_topic' AIRFLOW_CTX_EXECUTION_DATE='2024-01-01T00:00:00+00:00' AIRFLOW_CTX_TRY_NUMBER='3' AIRFLOW_CTX_DAG_RUN_ID='scheduled__2024-01-01T00:00:00+00:00'
[2024-01-05T17:45:26.413+0000] {taskinstance.py:2699} ERROR - Task failed with exception
Traceback (most recent call last):
  File "/home/airflow/.local/lib/python3.8/site-packages/airflow/models/taskinstance.py", line 433, in _execute_task
    result = execute_callable(context=context, **execute_callable_kwargs)
  File "/home/airflow/.local/lib/python3.8/site-packages/airflow/operators/python.py", line 199, in execute
    return_value = self.execute_callable()
  File "/home/airflow/.local/lib/python3.8/site-packages/airflow/operators/python.py", line 216, in execute_callable
    return self.python_callable(*self.op_args, **self.op_kwargs)
  File "/opt/airflow/dags/create_topic.py", line 20, in create_topic
    admin_client.close()
AttributeError: 'AdminClient' object has no attribute 'close'
[2024-01-05T17:45:26.418+0000] {taskinstance.py:1138} INFO - Marking task as FAILED. dag_id=create_topic, task_id=create_topic, execution_date=20240101T000000, start_date=20240105T174526, end_date=20240105T174526
[2024-01-05T17:45:26.424+0000] {standard_task_runner.py:107} ERROR - Failed to execute job 32 for task create_topic ('AdminClient' object has no attribute 'close'; 143)
[2024-01-05T17:45:26.438+0000] {local_task_job_runner.py:234} INFO - Task exited with return code 1
[2024-01-05T17:45:26.448+0000] {taskinstance.py:3281} INFO - 0 downstream tasks scheduled from follow-on schedule check
