[2024-01-05T16:17:20.684+0000] {taskinstance.py:1957} INFO - Dependencies all met for dep_context=non-requeueable deps ti=<TaskInstance: dag_metadata_collector.send_metadata_to_kafka scheduled__2024-01-01T00:00:00+00:00 [queued]>
[2024-01-05T16:17:20.689+0000] {taskinstance.py:1957} INFO - Dependencies all met for dep_context=requeueable deps ti=<TaskInstance: dag_metadata_collector.send_metadata_to_kafka scheduled__2024-01-01T00:00:00+00:00 [queued]>
[2024-01-05T16:17:20.689+0000] {taskinstance.py:2171} INFO - Starting attempt 19 of 19
[2024-01-05T16:17:20.696+0000] {taskinstance.py:2192} INFO - Executing <Task(PythonOperator): send_metadata_to_kafka> on 2024-01-01 00:00:00+00:00
[2024-01-05T16:17:20.699+0000] {standard_task_runner.py:60} INFO - Started process 297 to run task
[2024-01-05T16:17:20.701+0000] {standard_task_runner.py:87} INFO - Running: ['***', 'tasks', 'run', 'dag_metadata_collector', 'send_metadata_to_kafka', 'scheduled__2024-01-01T00:00:00+00:00', '--job-id', '45', '--raw', '--subdir', 'DAGS_FOLDER/dag_metadata_collector.py', '--cfg-path', '/tmp/tmp2lti962t']
[2024-01-05T16:17:20.702+0000] {standard_task_runner.py:88} INFO - Job 45: Subtask send_metadata_to_kafka
[2024-01-05T16:17:20.730+0000] {task_command.py:423} INFO - Running <TaskInstance: dag_metadata_collector.send_metadata_to_kafka scheduled__2024-01-01T00:00:00+00:00 [running]> on host 73232b21783f
[2024-01-05T16:17:20.768+0000] {taskinstance.py:2481} INFO - Exporting env vars: AIRFLOW_CTX_DAG_OWNER='***' AIRFLOW_CTX_DAG_ID='dag_metadata_collector' AIRFLOW_CTX_TASK_ID='send_metadata_to_kafka' AIRFLOW_CTX_EXECUTION_DATE='2024-01-01T00:00:00+00:00' AIRFLOW_CTX_TRY_NUMBER='19' AIRFLOW_CTX_DAG_RUN_ID='scheduled__2024-01-01T00:00:00+00:00'
[2024-01-05T16:17:20.778+0000] {taskinstance.py:2699} ERROR - Task failed with exception
Traceback (most recent call last):
  File "/home/airflow/.local/lib/python3.8/site-packages/airflow/models/taskinstance.py", line 433, in _execute_task
    result = execute_callable(context=context, **execute_callable_kwargs)
  File "/home/airflow/.local/lib/python3.8/site-packages/airflow/operators/python.py", line 199, in execute
    return_value = self.execute_callable()
  File "/home/airflow/.local/lib/python3.8/site-packages/airflow/operators/python.py", line 216, in execute_callable
    return self.python_callable(*self.op_args, **self.op_kwargs)
  File "/opt/airflow/dags/dag_metadata_collector.py", line 31, in send_metadata_to_kafka
    json_data = json.dumps(metadata)
  File "/usr/local/lib/python3.8/json/__init__.py", line 231, in dumps
    return _default_encoder.encode(obj)
  File "/usr/local/lib/python3.8/json/encoder.py", line 199, in encode
    chunks = self.iterencode(o, _one_shot=True)
  File "/usr/local/lib/python3.8/json/encoder.py", line 257, in iterencode
    return _iterencode(o, 0)
  File "/usr/local/lib/python3.8/json/encoder.py", line 179, in default
    raise TypeError(f'Object of type {o.__class__.__name__} '
TypeError: Object of type datetime is not JSON serializable
[2024-01-05T16:17:20.785+0000] {taskinstance.py:1138} INFO - Marking task as FAILED. dag_id=dag_metadata_collector, task_id=send_metadata_to_kafka, execution_date=20240101T000000, start_date=20240105T161720, end_date=20240105T161720
[2024-01-05T16:17:20.792+0000] {standard_task_runner.py:107} ERROR - Failed to execute job 45 for task send_metadata_to_kafka (Object of type datetime is not JSON serializable; 297)
[2024-01-05T16:17:20.837+0000] {local_task_job_runner.py:234} INFO - Task exited with return code 1
[2024-01-05T16:17:20.848+0000] {taskinstance.py:3281} INFO - 0 downstream tasks scheduled from follow-on schedule check
